Workbook

Sheet 1-133
A1: 001-000133--Lite Block Totes 160/6 lb | F1: Ttl. Tts. | G1: =B64+L64+V64+AF64+AP64+AZ64+BJ64 -> 0 | H1: Ttl. Wt. | I1: =D64+N64+X64+AH64+AR64+BB64+BL64 -> 0 | L1: 001-000133--Lite Block Totes 160/6 lb | V1: 001-000133--Lite Block Totes 160/6 lb | AF1: 001-000133--Lite Block Totes 160/6 lb | AP1: 001-000133--Lite Block Totes 160/6 lb | AZ1: 001-000133--Lite Block Totes 160/6 lb | BJ1: 001-000133--Lite Block Totes 160/6 lb
B2: Date= | H2: Firmness F=Firm S=Soft | I2: Delvicid Used Y/N | L2: Date= | R2: Firmness F=Firm S=Soft | S2: Delvicid Used Y/N | V2: Date= | AB2: Firmness F=Firm S=Soft | AC2: Delvicid Used Y/N | AF2: Date= | AL2: Firmness F=Firm S=Soft | AM2: Delvicid Used Y/N | AP2: Date= | AV2: Firmness F=Firm S=Soft | AW2: Delvicid Used Y/N | AZ2: Date= | BF2: Firmness F=Firm S=Soft | BG2: Delvicid Used Y/N | BJ2: Date= | BP2: Firmness F=Firm S=Soft | BQ2: Delvicid Used Y/N
B3: Tote/ Skid # | C3: Number of Pieces | D3: Bin Weight | E3: Time Started | F3: Temp | G3: Bin Seal Grade | J3: Int. | L3: Tote/ Skid # | M3: Number of Pieces | N3: Bin Weight | O3: Time Started | P3: Temp | Q3: Bin Seal Grade | T3: Int. | V3: Tote/ Skid # | W3: Number of Pieces | X3: Bin Weight | Y3: Time Started | Z3: Temp | AA3: Bin Seal Grade | AD3: Int. | AF3: Tote/ Skid # | AG3: Number of Pieces | AH3: Bin Weight | AI3: Time Started | AJ3: Temp | AK3: Bin Seal Grade | AN3: Int. | AP3: Tote/ Skid # | AQ3: Number of Pieces | AR3: Bin Weight | AS3: Time Started | AT3: Temp | AU3: Bin Seal Grade | AX3: Int. | AZ3: Tote/ Skid # | BA3: Number of Pieces | BB3: Bin Weight | BC3: Time Started | BD3: Temp | BE3: Bin Seal Grade | BH3: Int. | BJ3: Tote/ Skid # | BK3: Number of Pieces | BL3: Bin Weight | BM3: Time Started | BN3: Temp | BO3: Bin Seal Grade | BR3: Int.
A4: 1 | K4: 1 | U4: 1 | AE4: 1 | AO4: 1 | AY4: 1 | BI4: 1
A5: 2 | K5: 2 | U5: 2 | AE5: 2 | AO5: 2 | AY5: 2 | BI5: 2
A6: 3 | K6: 3 | U6: 3 | AE6: 3 | AO6: 3 | AY6: 3 | BI6: 3
A7: 4 | K7: 4 | U7: 4 | AE7: 4 | AO7: 4 | AY7: 4 | BI7: 4
A8: 5 | K8: 5 | U8: 5 | AE8: 5 | AO8: 5 | AY8: 5 | BI8: 5
A9: 6 | K9: 6 | U9: 6 | AE9: 6 | AO9: 6 | AY9: 6 | BI9: 6
A10: 7 | K10: 7 | U10: 7 | AE10: 7 | AO10: 7 | AY10: 7 | BI10: 7
A11: 8 | K11: 8 | U11: 8 | AE11: 8 | AO11: 8 | AY11: 8 | BI11: 8
A12: 9 | K12: 9 | U12: 9 | AE12: 9 | AO12: 9 | AY12: 9 | BI12: 9
A13: 10 | K13: 10 | U13: 10 | AE13: 10 | AO13: 10 | AY13: 10 | BI13: 10
A14: 11 | K14: 11 | U14: 11 | AE14: 11 | AO14: 11 | AY14: 11 | BI14: 11
A15: 12 | K15: 12 | U15: 12 | AE15: 12 | AO15: 12 | AY15: 12 | BI15: 12
... A63: 60 | K63: 60 | U63: 60 | AE63: 60 | AO63: 60 | AY63: 60 | BI63: 60
B64: =COUNTA(B4:B63) -> 0 | D64: =SUM(D4:D63) -> 0 | L64: =COUNTA(L4:L63) -> 0 | N64: =SUM(N4:N63) -> 0 | V64: =COUNTA(V4:V63) -> 0 | X64: =SUM(X4:X63) -> 0 | AF64: =COUNTA(AF4:AF63) -> 0 | AH64: =SUM(AH4:AH63) -> 0 | AP64: =COUNTA(AP4:AP63) -> 0 | AR64: =SUM(AR4:AR63) -> 0 | AZ64: =COUNTA(AZ4:AZ63) -> 0 | BB64: =SUM(BB4:BB63) -> 0 | BJ64: =COUNTA(BJ4:BJ63) -> 0 | BL64: =SUM(BL4:BL63) -> 0
B65: Total Bins of Date | D65: Total Weight of Date | L65: Total Bins of Date | N65: Total Weight of Date | V65: Total Bins of Date | X65: Total Weight of Date | AF65: Total Bins of Date | AH65: Total Weight of Date | AP65: Total Bins of Date | AR65: Total Weight of Date | AZ65: Total Bins of Date | BB65: Total Weight of Date | BJ65: Total Bins of Date | BL65: Total Weight of Date

Sheet 1-169
A1: 001-000169-Part Skim Block Totes 160/6 lb | F1: Ttl. Tts. | G1: =B64+L64+V64+AP64+AZ64+BJ64+BT64+CD64+CN64+CX64+DH64+DR64+AF64 -> 0 | H1: Ttl. Wt. | I1: =D64+N64+X64+AH64+AR64+BB64+BL64+BV64+CF64+CP64+CZ64+DJ64+DT64 -> 0 | L1: 001-000169--Part Skim Block Totes 160/6 lb | V1: 001-000169--Part Skim Block Totes 160/6 lb | AF1: 001-000169--Part Skim Block Totes 160/6 lb | AP1: 001-000169--Part Skim Block Totes 160/6 lb | AZ1: 001-000169--Part Skim Block Totes 160/6 lb | BJ1: 001-000169--Part Skim Block Totes 160/6 lb | BT1: 001-000169--Part Skim Block Totes 160/6 lb | CD1: 001-000169--Part Skim Block Totes 160/6 lb | CN1: 001-000169--Part Skim Block Totes 160/6 lb | CX1: 001-000169--Part Skim Block Totes 160/6 lb | DH1: 001-000169--Part Skim Block Totes 160/6 lb | DR1: 001-000169--Part Skim Block Totes 160/6 lb
B2: Date= | H2: Firmness F=Firm S=Soft | I2: Delvicid Used Y/N | L2: Date= | R2: Firmness F=Firm S=Soft | S2: Delvicid Used Y/N | V2: Date= | AB2: Firmness F=Firm S=Soft | AC2: Delvicid Used Y/N | AF2: Date= | AL2: Firmness F=Firm S=Soft | AM2: Delvicid Used Y/N | AP2: Date= | AV2: Firmness F=Firm S=Soft | AW2: Delvicid Used Y/N | AZ2: Date= | BF2: Firmness F=Firm S=Soft | BG2: Delvicid Used Y/N | BJ2: Date= | BP2: Firmness F=Firm S=Soft | BQ2: Delvicid Used Y/N | BT2: Date= | BZ2: Firmness F=Firm S=Soft | CA2: Delvicid Used Y/N | CD2: Date= | CJ2: Firmness F=Firm S=Soft | CK2: Delvicid Used Y/N | CN2: Date= | CT2: Firmness F=Firm S=Soft | CU2: Delvicid Used Y/N | CX2: Date= | DD2: Firmness F=Firm S=Soft | DE2: Delvicid Used Y/N | DH2: Date= | DN2: Firmness F=Firm S=Soft | DO2: Delvicid Used Y/N | DR2: Date= | DX2: Firmness F=Firm S=Soft | DY2: Delvicid Used Y/N
B3: Tote/ Skid # | C3: Number of Pieces | D3: Bin Weight | E3: Time Started | F3: Temp | G3: Bin Seal Grade | J3: Int. | L3: Tote/ Skid # | M3: Number of Pieces | N3: Bin Weight | O3: Time Started | P3: Temp | Q3: Bin Seal Grade | T3: Int. | V3: Tote/ Skid # | W3: Number of Pieces | X3: Bin Weight | Y3: Time Started | Z3: Temp | AA3: Bin Seal Grade | AD3: Int. | AF3: Tote/ Skid # | AG3: Number of Pieces | AH3: Bin Weight | AI3: Time Started | AJ3: Temp | AK3: Bin Seal Grade | AN3: Int. | AP3: Tote/ Skid # | AQ3: Number of Pieces | AR3: Bin Weight | AS3: Time Started | AT3: Temp | AU3: Bin Seal Grade | AX3: Int. | AZ3: Tote/ Skid # | BA3: Number of Pieces | BB3: Bin Weight | BC3: Time Started | BD3: Temp | BE3: Bin Seal Grade | BH3: Int. | BJ3: Tote/ Skid # | BK3: Number of Pieces | BL3: Bin Weight | BM3: Time Started | BN3: Temp | BO3: Bin Seal Grade | BR3: Int. | BT3: Tote/ Skid # | BU3: Number of Pieces | BV3: Bin Weight | BW3: Time Started | BX3: Temp | BY3: Bin Seal Grade | CB3: Int. | CD3: Tote/ Skid # | CE3: Number of Pieces | CF3: Bin Weight | CG3: Time Started | CH3: Temp | CI3: Bin Seal Grade | CL3: Int. | CN3: Tote/ Skid # | CO3: Number of Pieces | CP3: Bin Weight | CQ3: Time Started | CR3: Temp | CS3: Bin Seal Grade | CV3: Int. | CX3: Tote/ Skid # | CY3: Number of Pieces | CZ3: Bin Weight | DA3: Time Started | DB3: Temp | DC3: Bin Seal Grade | DF3: Int. | DH3: Tote/ Skid # | DI3: Number of Pieces | DJ3: Bin Weight | DK3: Time Started | DL3: Temp | DM3: Bin Seal Grade | DP3: Int. | DR3: Tote/ Skid # | DS3: Number of Pieces | DT3: Bin Weight | DU3: Time Started | DV3: Temp | DW3: Bin Seal Grade | DZ3: Int.
A4: 1 | K4: 1 | U4: 1 | AE4: 1 | AO4: 1 | AY4: 1 | BI4: 1 | BS4: 1 | CC4: 1 | CM4: 1 | CW4: 1 | DG4: 1 | DQ4: 1
A5: 2 | K5: 2 | U5: 2 | AE5: 2 | AO5: 2 | AY5: 2 | BI5: 2 | BS5: 2 | CC5: 2 | CM5: 2 | CW5: 2 | DG5: 2 | DQ5: 2
A6: 3 | K6: 3 | U6: 3 | AE6: 3 | AO6: 3 | AY6: 3 | BI6: 3 | BS6: 3 | CC6: 3 | CM6: 3 | CW6: 3 | DG6: 3 | DQ6: 3
A7: 4 | K7: 4 | U7: 4 | AE7: 4 | AO7: 4 | AY7: 4 | BI7: 4 | BS7: 4 | CC7: 4 | CM7: 4 | CW7: 4 | DG7: 4 | DQ7: 4
A8: 5 | K8: 5 | U8: 5 | AE8: 5 | AO8: 5 | AY8: 5 | BI8: 5 | BS8: 5 | CC8: 5 | CM8: 5 | CW8: 5 | DG8: 5 | DQ8: 5
A9: 6 | K9: 6 | U9: 6 | AE9: 6 | AO9: 6 | AY9: 6 | BI9: 6 | BS9: 6 | CC9: 6 | CM9: 6 | CW9: 6 | DG9: 6 | DQ9: 6
A10: 7 | K10: 7 | U10: 7 | AE10: 7 | AO10: 7 | AY10: 7 | BI10: 7 | BS10: 7 | CC10: 7 | CM10: 7 | CW10: 7 | DG10: 7 | DQ10: 7
A11: 8 | K11: 8 | U11: 8 | AE11: 8 | AO11: 8 | AY11: 8 | BI11: 8 | BS11: 8 | CC11: 8 | CM11: 8 | CW11: 8 | DG11: 8 | DQ11: 8
A12: 9 | K12: 9 | U12: 9 | AE12: 9 | AO12: 9 | AY12: 9 | BI12: 9 | BS12: 9 | CC12: 9 | CM12: 9 | CW12: 9 | DG12: 9 | DQ12: 9
A13: 10 | K13: 10 | U13: 10 | AE13: 10 | AO13: 10 | AY13: 10 | BI13: 10 | BS13: 10 | CC13: 10 | CM13: 10 | CW13: 10 | DG13: 10 | DQ13: 10
A14: 11 | K14: 11 | U14: 11 | AE14: 11 | AO14: 11 | AY14: 11 | BI14: 11 | BS14: 11 | CC14: 11 | CM14: 11 | CW14: 11 | DG14: 11 | DQ14: 11
A15: 12 | K15: 12 | U15: 12 | AE15: 12 | AO15: 12 | AY15: 12 | BI15: 12 | BS15: 12 | CC15: 12 | CM15: 12 | CW15: 12 | DG15: 12 | DQ15: 12
... A63: 60 | K63: 60 | U63: 60 | AE63: 60 | AO63: 60 | AY63: 60 | BI63: 60 | BS63: 60 | CC63: 60 | CM63: 60 | CW63: 60 | DG63: 60 | DQ63: 60
B64: =COUNTA(B4:B63) -> 0 | D64: =SUM(D4:D63) -> 0 | L64: =COUNTA(L4:L63) -> 0 | N64: =SUM(N4:N63) -> 0 | V64: =COUNTA(V4:V63) -> 0 | X64: =SUM(X4:X63) -> 0 | AF64: =COUNTA(AF4:AF63) -> 0 | AH64: =SUM(AH4:AH63) -> 0 | AP64: =COUNTA(AP4:AP63) -> 0 | AR64: =SUM(AR4:AR63) -> 0 | AZ64: =COUNTA(AZ4:AZ63) -> 0 | BB64: =SUM(BB4:BB63) -> 0 | BJ64: =COUNTA(BJ4:BJ63) -> 0 | BL64: =SUM(BL4:BL63) -> 0 | BT64: =COUNTA(BT4:BT63) -> 0 | BV64: =SUM(BV4:BV63) -> 0 | CD64: =COUNTA(CD4:CD63) -> 0 | CF64: =SUM(CF4:CF63) -> 0 | CN64: =COUNTA(CN4:CN63) -> 0 | CP64: =SUM(CP4:CP63) -> 0 | CX64: =COUNTA(CX4:CX63) -> 0 | CZ64: =SUM(CZ4:CZ63) -> 0 | DH64: =COUNTA(DH4:DH63) -> 0 | DJ64: =SUM(DJ4:DJ63) -> 0 | DR64: =COUNTA(DR4:DR63) -> 0 | DT64: =SUM(DT4:DT63) -> 0
B65: Total Bins of Date | D65: Total Weight of Date | L65: Total Bins of Date | N65: Total Weight of Date | V65: Total Bins of Date | X65: Total Weight of Date | AF65: Total Bins of Date | AH65: Total Weight of Date | AP65: Total Bins of Date | AR65: Total Weight of Date | AZ65: Total Bins of Date | BB65: Total Weight of Date | BJ65: Total Bins of Date | BL65: Total Weight of Date | BT65: Total Bins of Date | BV65: Total Weight of Date | CD65: Total Bins of Date | CF65: Total Weight of Date | CN65: Total Bins of Date | CP65: Total Weight of Date | CX65: Total Bins of Date | CZ65: Total Weight of Date | DH65: Total Bins of Date | DJ65: Total Weight of Date | DR65: Total Bins of Date | DT65: Total Weight of Date

Sheet 1-195
A1: 001-000195--Organic Block Totes 160/6 lb | F1: Ttl. Tts. | G1: =B64+L64+V64+AF64+AP64+AZ64+BJ64 -> 0 | H1: Ttl. Wt. | I1: =D64+N64+X64+AH64+AR64+BB64+BL64 -> 0 | L1: 001-000195--Organic Block Totes 160/6 lb | V1: 001-000195--Organic Block Totes 160/6 lb | AF1: 001-000195--Organic Block Totes 160/6 lb | AP1: 001-000195--Organic Block Totes 160/6 lb | AZ1: 001-000195--Organic Block Totes 160/6 lb | BJ1: 001-000195--Organic Block Totes 160/6 lb
B2: Date= | H2: Firmness F=Firm S=Soft | I2: Delvicid Used Y/N | L2: Date= | R2: Firmness F=Firm S=Soft | S2: Delvicid Used Y/N | V2: Date= | AB2: Firmness F=Firm S=Soft | AC2: Delvicid Used Y/N | AF2: Date= | AL2: Firmness F=Firm S=Soft | AM2: Delvicid Used Y/N | AP2: Date= | AV2: Firmness F=Firm S=Soft | AW2: Delvicid Used Y/N | AZ2: Date= | BF2: Firmness F=Firm S=Soft | BG2: Delvicid Used Y/N | BJ2: Date= | BP2: Firmness F=Firm S=Soft | BQ2: Delvicid Used Y/N
B3: Tote/ Skid # | C3: Number of Pieces | D3: Bin Weight | E3: Time Started | F3: Temp | G3: Bin Seal Grade | J3: Int. | L3: Tote/ Skid # | M3: Number of Pieces | N3: Bin Weight | O3: Time Started | P3: Temp | Q3: Bin Seal Grade | T3: Int. | V3: Tote/ Skid # | W3: Number of Pieces | X3: Bin Weight | Y3: Time Started | Z3: Temp | AA3: Bin Seal Grade | AD3: Int. | AF3: Tote/ Skid # | AG3: Number of Pieces | AH3: Bin Weight | AI3: Time Started | AJ3: Temp | AK3: Bin Seal Grade | AN3: Int. | AP3: Tote/ Skid # | AQ3: Number of Pieces | AR3: Bin Weight | AS3: Time Started | AT3: Temp | AU3: Bin Seal Grade | AX3: Int. | AZ3: Tote/ Skid # | BA3: Number of Pieces | BB3: Bin Weight | BC3: Time Started | BD3: Temp | BE3: Bin Seal Grade | BH3: Int. | BJ3: Tote/ Skid # | BK3: Number of Pieces | BL3: Bin Weight | BM3: Time Started | BN3: Temp | BO3: Bin Seal Grade | BR3: Int.
A4: 1 | K4: 1 | U4: 1 | AE4: 1 | AO4: 1 | AY4: 1 | BI4: 1
A5: 2 | K5: 2 | U5: 2 | AE5: 2 | AO5: 2 | AY5: 2 | BI5: 2
A6: 3 | K6: 3 | U6: 3 | AE6: 3 | AO6: 3 | AY6: 3 | BI6: 3
A7: 4 | K7: 4 | U7: 4 | AE7: 4 | AO7: 4 | AY7: 4 | BI7: 4
A8: 5 | K8: 5 | U8: 5 | AE8: 5 | AO8: 5 | AY8: 5 | BI8: 5
A9: 6 | K9: 6 | U9: 6 | AE9: 6 | AO9: 6 | AY9: 6 | BI9: 6
A10: 7 | K10: 7 | U10: 7 | AE10: 7 | AO10: 7 | AY10: 7 | BI10: 7
A11: 8 | K11: 8 | U11: 8 | AE11: 8 | AO11: 8 | AY11: 8 | BI11: 8
A12: 9 | K12: 9 | U12: 9 | AE12: 9 | AO12: 9 | AY12: 9 | BI12: 9
A13: 10 | K13: 10 | U13: 10 | AE13: 10 | AO13: 10 | AY13: 10 | BI13: 10
A14: 11 | K14: 11 | U14: 11 | AE14: 11 | AO14: 11 | AY14: 11 | BI14: 11
A15: 12 | K15: 12 | U15: 12 | AE15: 12 | AO15: 12 | AY15: 12 | BI15: 12
... A63: 60 | K63: 60 | U63: 60 | AE63: 60 | AO63: 60 | AY63: 60 | BI63: 60
B64: =COUNTA(B4:B63) -> 0 | D64: =SUM(D4:D63) -> 0 | L64: =COUNTA(L4:L63) -> 0 | N64: =SUM(N4:N63) -> 0 | V64: =COUNTA(V4:V63) -> 0 | X64: =SUM(X4:X63) -> 0 | AF64: =COUNTA(AF4:AF63) -> 0 | AH64: =SUM(AH4:AH63) -> 0 | AP64: =COUNTA(AP4:AP63) -> 0 | AR64: =SUM(AR4:AR63) -> 0 | AZ64: =COUNTA(AZ4:AZ63) -> 0 | BB64: =SUM(BB4:BB63) -> 0 | BJ64: =COUNTA(BJ4:BJ63) -> 0 | BL64: =SUM(BL4:BL63) -> 0
B65: Total Bins of Date | D65: Total Weight of Date | L65: Total Bins of Date | N65: Total Weight of Date | V65: Total Bins of Date | X65: Total Weight of Date | AF65: Total Bins of Date | AH65: Total Weight of Date | AP65: Total Bins of Date | AR65: Total Weight of Date | AZ65: Total Bins of Date | BB65: Total Weight of Date | BJ65: Total Bins of Date | BL65: Total Weight of Date

Sheet 1-229
A1: 001-000229--Provolone Block Totes 160/6 lb | F1: Ttl. Tts. | G1: =B64+L64+V64+AF64+AP64+AZ64+BJ64 -> 0 | H1: Ttl. Wt. | I1: =D64+N64+X64+AH64+AR64+BB64+BL64 -> 0 | L1: 001-000229--Provolone Block Totes 160/6 lb | V1: 001-000229--Provolone Block Totes 160/6 lb | AF1: 001-000229--Provolone Block Totes 160/6 lb | AP1: 001-000229--Provolone Block Totes 160/6 lb | AZ1: 001-000229--Provolone Block Totes 160/6 lb | BJ1: 001-000229--Provolone Block Totes 160/6 lb
B2: Date= | H2: Firmness F=Firm S=Soft | I2: Delvicid Used Y/N | L2: Date= | R2: Firmness F=Firm S=Soft | S2: Delvicid Used Y/N | V2: Date= | AB2: Firmness F=Firm S=Soft | AC2: Delvicid Used Y/N | AF2: Date= | AL2: Firmness F=Firm S=Soft | AM2: Delvicid Used Y/N | AP2: Date= | AV2: Firmness F=Firm S=Soft | AW2: Delvicid Used Y/N | AZ2: Date= | BF2: Firmness F=Firm S=Soft | BG2: Delvicid Used Y/N | BJ2: Date= | BP2: Firmness F=Firm S=Soft | BQ2: Delvicid Used Y/N
B3: Tote/ Skid # | C3: Number of Pieces | D3: Bin Weight | E3: Time Started | F3: Temp | G3: Bin Seal Grade | J3: Int. | L3: Tote/ Skid # | M3: Number of Pieces | N3: Bin Weight | O3: Time Started | P3: Temp | Q3: Bin Seal Grade | T3: Int. | V3: Tote/ Skid # | W3: Number of Pieces | X3: Bin Weight | Y3: Time Started | Z3: Temp | AA3: Bin Seal Grade | AD3: Int. | AF3: Tote/ Skid # | AG3: Number of Pieces | AH3: Bin Weight | AI3: Time Started | AJ3: Temp | AK3: Bin Seal Grade | AN3: Int. | AP3: Tote/ Skid # | AQ3: Number of Pieces | AR3: Bin Weight | AS3: Time Started | AT3: Temp | AU3: Bin Seal Grade | AX3: Int. | AZ3: Tote/ Skid # | BA3: Number of Pieces | BB3: Bin Weight | BC3: Time Started | BD3: Temp | BE3: Bin Seal Grade | BH3: Int. | BJ3: Tote/ Skid # | BK3: Number of Pieces | BL3: Bin Weight | BM3: Time Started | BN3: Temp | BO3: Bin Seal Grade | BR3: Int.
A4: 1 | K4: 1 | U4: 1 | AE4: 1 | AO4: 1 | AY4: 1 | BI4: 1
A5: 2 | K5: 2 | U5: 2 | AE5: 2 | AO5: 2 | AY5: 2 | BI5: 2
A6: 3 | K6: 3 | U6: 3 | AE6: 3 | AO6: 3 | AY6: 3 | BI6: 3
A7: 4 | K7: 4 | U7: 4 | AE7: 4 | AO7: 4 | AY7: 4 | BI7: 4
A8: 5 | K8: 5 | U8: 5 | AE8: 5 | AO8: 5 | AY8: 5 | BI8: 5
A9: 6 | K9: 6 | U9: 6 | AE9: 6 | AO9: 6 | AY9: 6 | BI9: 6
A10: 7 | K10: 7 | U10: 7 | AE10: 7 | AO10: 7 | AY10: 7 | BI10: 7
A11: 8 | K11: 8 | U11: 8 | AE11: 8 | AO11: 8 | AY11: 8 | BI11: 8
A12: 9 | K12: 9 | U12: 9 | AE12: 9 | AO12: 9 | AY12: 9 | BI12: 9
A13: 10 | K13: 10 | U13: 10 | AE13: 10 | AO13: 10 | AY13: 10 | BI13: 10
A14: 11 | K14: 11 | U14: 11 | AE14: 11 | AO14: 11 | AY14: 11 | BI14: 11
A15: 12 | K15: 12 | U15: 12 | AE15: 12 | AO15: 12 | AY15: 12 | BI15: 12
... A63: 60 | K63: 60 | U63: 60 | AE63: 60 | AO63: 60 | AY63: 60 | BI63: 60
B64: =COUNTA(B4:B63) -> 0 | D64: =SUM(D4:D63) -> 0 | L64: =COUNTA(L4:L63) -> 0 | N64: =SUM(N4:N63) -> 0 | V64: =COUNTA(V4:V63) -> 0 | X64: =SUM(X4:X63) -> 0 | AF64: =COUNTA(AF4:AF63) -> 0 | AH64: =SUM(AH4:AH63) -> 0 | AP64: =COUNTA(AP4:AP63) -> 0 | AR64: =SUM(AR4:AR63) -> 0 | AZ64: =COUNTA(AZ4:AZ63) -> 0 | BB64: =SUM(BB4:BB63) -> 0 | BJ64: =COUNTA(BJ4:BJ63) -> 0 | BL64: =SUM(BL4:BL63) -> 0
B65: Total Bins of Date | D65: Total Weight of Date | L65: Total Bins of Date | N65: Total Weight of Date | V65: Total Bins of Date | X65: Total Weight of Date | AF65: Total Bins of Date | AH65: Total Weight of Date | AP65: Total Bins of Date | AR65: Total Weight of Date | AZ65: Total Bins of Date | BB65: Total Weight of Date | BJ65: Total Bins of Date | BL65: Total Weight of Date

Sheet 1-360
A1: 001-000360-Red Fat Block Totes 160/6 lb | F1: Ttl. Tts. | G1: =B64+L64+V64+AF64+AP64+AZ64+BJ64 -> 0 | H1: Ttl. Wt. | I1: =D64+N64+X64+AH64+AR64+BB64+BL64 -> 0 | L1: 001-000360--Red Fat Block Totes 160/6 lb | V1: 001-000360--Red Fat Block Totes 160/6 lb | AF1: 001-000360--Red Fat Block Totes 160/6 lb | AP1: 001-000360--Red Fat Block Totes 160/6 lb | AZ1: 001-000360--Red Fat Block Totes 160/6 lb | BJ1: 001-000360--Red Fat Block Totes 160/6 lb
B2: Date= | H2: Firmness F=Firm S=Soft | I2: Delvicid Used Y/N | L2: Date= | R2: Firmness F=Firm S=Soft | S2: Delvicid Used Y/N | V2: Date= | AB2: Firmness F=Firm S=Soft | AC2: Delvicid Used Y/N | AF2: Date= | AL2: Firmness F=Firm S=Soft | AM2: Delvicid Used Y/N | AP2: Date= | AV2: Firmness F=Firm S=Soft | AW2: Delvicid Used Y/N | AZ2: Date= | BF2: Firmness F=Firm S=Soft | BG2: Delvicid Used Y/N | BJ2: Date= | BP2: Firmness F=Firm S=Soft | BQ2: Delvicid Used Y/N
B3: Tote/ Skid # | C3: Number of Pieces | D3: Bin Weight | E3: Time Started | F3: Temp | G3: Bin Seal Grade | J3: Int. | L3: Tote/ Skid # | M3: Number of Pieces | N3: Bin Weight | O3: Time Started | P3: Temp | Q3: Bin Seal Grade | T3: Int. | V3: Tote/ Skid # | W3: Number of Pieces | X3: Bin Weight | Y3: Time Started | Z3: Temp | AA3: Bin Seal Grade | AD3: Int. | AF3: Tote/ Skid # | AG3: Number of Pieces | AH3: Bin Weight | AI3: Time Started | AJ3: Temp | AK3: Bin Seal Grade | AN3: Int. | AP3: Tote/ Skid # | AQ3: Number of Pieces | AR3: Bin Weight | AS3: Time Started | AT3: Temp | AU3: Bin Seal Grade | AX3: Int. | AZ3: Tote/ Skid # | BA3: Number of Pieces | BB3: Bin Weight | BC3: Time Started | BD3: Temp | BE3: Bin Seal Grade | BH3: Int. | BJ3: Tote/ Skid # | BK3: Number of Pieces | BL3: Bin Weight | BM3: Time Started | BN3: Temp | BO3: Bin Seal Grade | BR3: Int.
A4: 1 | K4: 1 | U4: 1 | AE4: 1 | AO4: 1 | AY4: 1 | BI4: 1
A5: 2 | K5: 2 | U5: 2 | AE5: 2 | AO5: 2 | AY5: 2 | BI5: 2
A6: 3 | K6: 3 | U6: 3 | AE6: 3 | AO6: 3 | AY6: 3 | BI6: 3
A7: 4 | K7: 4 | U7: 4 | AE7: 4 | AO7: 4 | AY7: 4 | BI7: 4
A8: 5 | K8: 5 | U8: 5 | AE8: 5 | AO8: 5 | AY8: 5 | BI8: 5
A9: 6 | K9: 6 | U9: 6 | AE9: 6 | AO9: 6 | AY9: 6 | BI9: 6
A10: 7 | K10: 7 | U10: 7 | AE10: 7 | AO10: 7 | AY10: 7 | BI10: 7
A11: 8 | K11: 8 | U11: 8 | AE11: 8 | AO11: 8 | AY11: 8 | BI11: 8
A12: 9 | K12: 9 | U12: 9 | AE12: 9 | AO12: 9 | AY12: 9 | BI12: 9
A13: 10 | K13: 10 | U13: 10 | AE13: 10 | AO13: 10 | AY13: 10 | BI13: 10
A14: 11 | K14: 11 | U14: 11 | AE14: 11 | AO14: 11 | AY14: 11 | BI14: 11
A15: 12 | K15: 12 | U15: 12 | AE15: 12 | AO15: 12 | AY15: 12 | BI15: 12
... A63: 60 | K63: 60 | U63: 60 | AE63: 60 | AO63: 60 | AY63: 60 | BI63: 60
B64: =COUNTA(B4:B63) -> 0 | D64: =SUM(D4:D63) -> 0 | L64: =COUNTA(L4:L63) -> 0 | N64: =SUM(N4:N63) -> 0 | V64: =COUNTA(V4:V63) -> 0 | X64: =SUM(X4:X63) -> 0 | AF64: =COUNTA(AF4:AF63) -> 0 | AH64: =SUM(AH4:AH63) -> 0 | AP64: =COUNTA(AP4:AP63) -> 0 | AR64: =SUM(AR4:AR63) -> 0 | AZ64: =COUNTA(AZ4:AZ63) -> 0 | BB64: =SUM(BB4:BB63) -> 0 | BJ64: =COUNTA(BJ4:BJ63) -> 0 | BL64: =SUM(BL4:BL63) -> 0
B65: Total Bins of Date | D65: Total Weight of Date | L65: Total Bins of Date | N65: Total Weight of Date | V65: Total Bins of Date | X65: Total Weight of Date | AF65: Total Bins of Date | AH65: Total Weight of Date | AP65: Total Bins of Date | AR65: Total Weight of Date | AZ65: Total Bins of Date | BB65: Total Weight of Date | BJ65: Total Bins of Date | BL65: Total Weight of Date

Sheet 1-455
A1: 001-000455-Nestle Org. Block Totes 160/6 lb | F1: Ttl. Tts. | G1: =B64+L64+V64+AF64+AP64+AZ64+BJ64 -> 0 | H1: Ttl. Wt. | I1: =D64+N64+X64+AH64+AR64+BB64+BL64 -> 0 | L1: 001-000455-Nestle Org. Block Totes 160/6 lb | V1: 001-000455-Nestle Org. Block Totes 160/6 lb | AF1: 001-000455-Nestle Org. Block Totes 160/6 lb | AP1: 001-000455-Nestle Org. Block Totes 160/6 lb | AZ1: 001-000455-Nestle Org. Block Totes 160/6 lb | BJ1: 001-000455-Nestle Org. Block Totes 160/6 lb
B2: Date= | H2: Firmness F=Firm S=Soft | I2: Delvicid Used Y/N | L2: Date= | R2: Firmness F=Firm S=Soft | S2: Delvicid Used Y/N | V2: Date= | AB2: Firmness F=Firm S=Soft | AC2: Delvicid Used Y/N | AF2: Date= | AL2: Firmness F=Firm S=Soft | AM2: Delvicid Used Y/N | AP2: Date= | AV2: Firmness F=Firm S=Soft | AW2: Delvicid Used Y/N | AZ2: Date= | BF2: Firmness F=Firm S=Soft | BG2: Delvicid Used Y/N | BJ2: Date= | BP2: Firmness F=Firm S=Soft | BQ2: Delvicid Used Y/N
B3: Tote/ Skid # | C3: Number of Pieces | D3: Bin Weight | E3: Time Started | F3: Temp | G3: Bin Seal Grade | J3: Int. | L3: Tote/ Skid # | M3: Number of Pieces | N3: Bin Weight | O3: Time Started | P3: Temp | Q3: Bin Seal Grade | T3: Int. | V3: Tote/ Skid # | W3: Number of Pieces | X3: Bin Weight | Y3: Time Started | Z3: Temp | AA3: Bin Seal Grade | AD3: Int. | AF3: Tote/ Skid # | AG3: Number of Pieces | AH3: Bin Weight | AI3: Time Started | AJ3: Temp | AK3: Bin Seal Grade | AN3: Int. | AP3: Tote/ Skid # | AQ3: Number of Pieces | AR3: Bin Weight | AS3: Time Started | AT3: Temp | AU3: Bin Seal Grade | AX3: Int. | AZ3: Tote/ Skid # | BA3: Number of Pieces | BB3: Bin Weight | BC3: Time Started | BD3: Temp | BE3: Bin Seal Grade | BH3: Int. | BJ3: Tote/ Skid # | BK3: Number of Pieces | BL3: Bin Weight | BM3: Time Started | BN3: Temp | BO3: Bin Seal Grade | BR3: Int.
A4: 1 | K4: 1 | U4: 1 | AE4: 1 | AO4: 1 | AY4: 1 | BI4: 1
A5: 2 | K5: 2 | U5: 2 | AE5: 2 | AO5: 2 | AY5: 2 | BI5: 2
A6: 3 | K6: 3 | U6: 3 | AE6: 3 | AO6: 3 | AY6: 3 | BI6: 3
A7: 4 | K7: 4 | U7: 4 | AE7: 4 | AO7: 4 | AY7: 4 | BI7: 4
A8: 5 | K8: 5 | U8: 5 | AE8: 5 | AO8: 5 | AY8: 5 | BI8: 5
A9: 6 | K9: 6 | U9: 6 | AE9: 6 | AO9: 6 | AY9: 6 | BI9: 6
A10: 7 | K10: 7 | U10: 7 | AE10: 7 | AO10: 7 | AY10: 7 | BI10: 7
A11: 8 | K11: 8 | U11: 8 | AE11: 8 | AO11: 8 | AY11: 8 | BI11: 8
A12: 9 | K12: 9 | U12: 9 | AE12: 9 | AO12: 9 | AY12: 9 | BI12: 9
A13: 10 | K13: 10 | U13: 10 | AE13: 10 | AO13: 10 | AY13: 10 | BI13: 10
A14: 11 | K14: 11 | U14: 11 | AE14: 11 | AO14: 11 | AY14: 11 | BI14: 11
A15: 12 | K15: 12 | U15: 12 | AE15: 12 | AO15: 12 | AY15: 12 | BI15: 12
... A63: 60 | K63: 60 | U63: 60 | AE63: 60 | AO63: 60 | AY63: 60 | BI63: 60
B64: =COUNTA(B4:B63) -> 0 | D64: =SUM(D4:D63) -> 0 | L64: =COUNTA(L4:L63) -> 0 | N64: =SUM(N4:N63) -> 0 | V64: =COUNTA(V4:V63) -> 0 | X64: =SUM(X4:X63) -> 0 | AF64: =COUNTA(AF4:AF63) -> 0 | AH64: =SUM(AH4:AH63) -> 0 | AP64: =COUNTA(AP4:AP63) -> 0 | AR64: =SUM(AR4:AR63) -> 0 | AZ64: =COUNTA(AZ4:AZ63) -> 0 | BB64: =SUM(BB4:BB63) -> 0 | BJ64: =COUNTA(BJ4:BJ63) -> 0 | BL64: =SUM(BL4:BL63) -> 0
B65: Total Bins of Date | D65: Total Weight of Date | L65: Total Bins of Date | N65: Total Weight of Date | V65: Total Bins of Date | X65: Total Weight of Date | AF65: Total Bins of Date | AH65: Total Weight of Date | AP65: Total Bins of Date | AR65: Total Weight of Date | AZ65: Total Bins of Date | BB65: Total Weight of Date | BJ65: Total Bins of Date | BL65: Total Weight of Date

Sheet 1-470
A1: 001-000470-RbstFree PS Block Totes 160/6 lb | F1: Ttl. Tts. | G1: =B64+L64+V64+AF64+AP64+AZ64+BJ64 -> 0 | H1: Ttl. Wt. | I1: =D64+N64+X64+AH64+AR64+BB64+BL64 -> 0 | L1: 001-000470-RbstFree PS Block Totes 160/6 lb | V1: 001-000470-RbstFree PS Block Totes 160/6 lb | AF1: 001-000470-RbstFree PS Block Totes 160/6 lb | AP1: 001-000470-RbstFree PS Block Totes 160/6 lb | AZ1: 001-000470-RbstFree PS Block Totes 160/6 lb | BJ1: 001-000470-RbstFree PS Block Totes 160/6 lb
B2: Date= | H2: Firmness F=Firm S=Soft | I2: Delvicid Used Y/N | L2: Date= | R2: Firmness F=Firm S=Soft | S2: Delvicid Used Y/N | V2: Date= | AB2: Firmness F=Firm S=Soft | AC2: Delvicid Used Y/N | AF2: Date= | AL2: Firmness F=Firm S=Soft | AM2: Delvicid Used Y/N | AP2: Date= | AV2: Firmness F=Firm S=Soft | AW2: Delvicid Used Y/N | AZ2: Date= | BF2: Firmness F=Firm S=Soft | BG2: Delvicid Used Y/N | BJ2: Date= | BP2: Firmness F=Firm S=Soft | BQ2: Delvicid Used Y/N
B3: Tote/ Skid # | C3: Number of Pieces | D3: Bin Weight | E3: Time Started | F3: Temp | G3: Bin Seal Grade | J3: Int. | L3: Tote/ Skid # | M3: Number of Pieces | N3: Bin Weight | O3: Time Started | P3: Temp | Q3: Bin Seal Grade | T3: Int. | V3: Tote/ Skid # | W3: Number of Pieces | X3: Bin Weight | Y3: Time Started | Z3: Temp | AA3: Bin Seal Grade | AD3: Int. | AF3: Tote/ Skid # | AG3: Number of Pieces | AH3: Bin Weight | AI3: Time Started | AJ3: Temp | AK3: Bin Seal Grade | AN3: Int. | AP3: Tote/ Skid # | AQ3: Number of Pieces | AR3: Bin Weight | AS3: Time Started | AT3: Temp | AU3: Bin Seal Grade | AX3: Int. | AZ3: Tote/ Skid # | BA3: Number of Pieces | BB3: Bin Weight | BC3: Time Started | BD3: Temp | BE3: Bin Seal Grade | BH3: Int. | BJ3: Tote/ Skid # | BK3: Number of Pieces | BL3: Bin Weight | BM3: Time Started | BN3: Temp | BO3: Bin Seal Grade | BR3: Int.
A4: 1 | K4: 1 | U4: 1 | AE4: 1 | AO4: 1 | AY4: 1 | BI4: 1
A5: 2 | K5: 2 | U5: 2 | AE5: 2 | AO5: 2 | AY5: 2 | BI5: 2
A6: 3 | K6: 3 | U6: 3 | AE6: 3 | AO6: 3 | AY6: 3 | BI6: 3
A7: 4 | K7: 4 | U7: 4 | AE7: 4 | AO7: 4 | AY7: 4 | BI7: 4
A8: 5 | K8: 5 | U8: 5 | AE8: 5 | AO8: 5 | AY8: 5 | BI8: 5
A9: 6 | K9: 6 | U9: 6 | AE9: 6 | AO9: 6 | AY9: 6 | BI9: 6
A10: 7 | K10: 7 | U10: 7 | AE10: 7 | AO10: 7 | AY10: 7 | BI10: 7
A11: 8 | K11: 8 | U11: 8 | AE11: 8 | AO11: 8 | AY11: 8 | BI11: 8
A12: 9 | K12: 9 | U12: 9 | AE12: 9 | AO12: 9 | AY12: 9 | BI12: 9
A13: 10 | K13: 10 | U13: 10 | AE13: 10 | AO13: 10 | AY13: 10 | BI13: 10
A14: 11 | K14: 11 | U14: 11 | AE14: 11 | AO14: 11 | AY14: 11 | BI14: 11
A15: 12 | K15: 12 | U15: 12 | AE15: 12 | AO15: 12 | AY15: 12 | BI15: 12
... A63: 60 | K63: 60 | U63: 60 | AE63: 60 | AO63: 60 | AY63: 60 | BI63: 60
B64: =COUNTA(B4:B63) -> 0 | D64: =SUM(D4:D63) -> 0 | L64: =COUNTA(L4:L63) -> 0 | N64: =SUM(N4:N63) -> 0 | V64: =COUNTA(V4:V63) -> 0 | X64: =SUM(X4:X63) -> 0 | AF64: =COUNTA(AF4:AF63) -> 0 | AH64: =SUM(AH4:AH63) -> 0 | AP64: =COUNTA(AP4:AP63) -> 0 | AR64: =SUM(AR4:AR63) -> 0 | AZ64: =COUNTA(AZ4:AZ63) -> 0 | BB64: =SUM(BB4:BB63) -> 0 | BJ64: =COUNTA(BJ4:BJ63) -> 0 | BL64: =SUM(BL4:BL63) -> 0
B65: Total Bins of Date | D65: Total Weight of Date | L65: Total Bins of Date | N65: Total Weight of Date | V65: Total Bins of Date | X65: Total Weight of Date | AF65: Total Bins of Date | AH65: Total Weight of Date | AP65: Total Bins of Date | AR65: Total Weight of Date | AZ65: Total Bins of Date | BB65: Total Weight of Date | BJ65: Total Bins of Date | BL65: Total Weight of Date

Sheet 1-712
A1: 001-000712--PS NN Block Totes 160/6 lb | F1: Ttl. Tts. | G1: =B64+L64+V64+AF64+AP64+AZ64+BJ64 -> 0 | H1: Ttl. Wt. | I1: =D64+N64+X64+AH64+AR64+BB64+BL64 -> 0 | L1: 001-000712--PS NN Block Totes 160/6 lb | V1: 001-000712--PS NN Block Totes 160/6 lb | AF1: 001-000712--PS NN Block Totes 160/6 lb | AP1: 001-000712--PS NN Block Totes 160/6 lb | AZ1: 001-000712--PS NN Block Totes 160/6 lb | BJ1: 001-000712--PS NN Block Totes 160/6 lb
B2: Date= | H2: Firmness F=Firm S=Soft | I2: Delvicid Used Y/N | L2: Date= | R2: Firmness F=Firm S=Soft | S2: Delvicid Used Y/N | V2: Date= | AB2: Firmness F=Firm S=Soft | AC2: Delvicid Used Y/N | AF2: Date= | AL2: Firmness F=Firm S=Soft | AM2: Delvicid Used Y/N | AP2: Date= | AV2: Firmness F=Firm S=Soft | AW2: Delvicid Used Y/N | AZ2: Date= | BF2: Firmness F=Firm S=Soft | BG2: Delvicid Used Y/N | BJ2: Date= | BP2: Firmness F=Firm S=Soft | BQ2: Delvicid Used Y/N
B3: Tote/ Skid # | C3: Number of Pieces | D3: Bin Weight | E3: Time Started | F3: Temp | G3: Bin Seal Grade | J3: Int. | L3: Tote/ Skid # | M3: Number of Pieces | N3: Bin Weight | O3: Time Started | P3: Temp | Q3: Bin Seal Grade | T3: Int. | V3: Tote/ Skid # | W3: Number of Pieces | X3: Bin Weight | Y3: Time Started | Z3: Temp | AA3: Bin Seal Grade | AD3: Int. | AF3: Tote/ Skid # | AG3: Number of Pieces | AH3: Bin Weight | AI3: Time Started | AJ3: Temp | AK3: Bin Seal Grade | AN3: Int. | AP3: Tote/ Skid # | AQ3: Number of Pieces | AR3: Bin Weight | AS3: Time Started | AT3: Temp | AU3: Bin Seal Grade | AX3: Int. | AZ3: Tote/ Skid # | BA3: Number of Pieces | BB3: Bin Weight | BC3: Time Started | BD3: Temp | BE3: Bin Seal Grade | BH3: Int. | BJ3: Tote/ Skid # | BK3: Number of Pieces | BL3: Bin Weight | BM3: Time Started | BN3: Temp | BO3: Bin Seal Grade | BR3: Int.
A4: 1 | K4: 1 | U4: 1 | AE4: 1 | AO4: 1 | AY4: 1 | BI4: 1
A5: 2 | K5: 2 | U5: 2 | AE5: 2 | AO5: 2 | AY5: 2 | BI5: 2
A6: 3 | K6: 3 | U6: 3 | AE6: 3 | AO6: 3 | AY6: 3 | BI6: 3
A7: 4 | K7: 4 | U7: 4 | AE7: 4 | AO7: 4 | AY7: 4 | BI7: 4
A8: 5 | K8: 5 | U8: 5 | AE8: 5 | AO8: 5 | AY8: 5 | BI8: 5
A9: 6 | K9: 6 | U9: 6 | AE9: 6 | AO9: 6 | AY9: 6 | BI9: 6
A10: 7 | K10: 7 | U10: 7 | AE10: 7 | AO10: 7 | AY10: 7 | BI10: 7
A11: 8 | K11: 8 | U11: 8 | AE11: 8 | AO11: 8 | AY11: 8 | BI11: 8
A12: 9 | K12: 9 | U12: 9 | AE12: 9 | AO12: 9 | AY12: 9 | BI12: 9
A13: 10 | K13: 10 | U13: 10 | AE13: 10 | AO13: 10 | AY13: 10 | BI13: 10
A14: 11 | K14: 11 | U14: 11 | AE14: 11 | AO14: 11 | AY14: 11 | BI14: 11
A15: 12 | K15: 12 | U15: 12 | AE15: 12 | AO15: 12 | AY15: 12 | BI15: 12
... A63: 60 | K63: 60 | U63: 60 | AE63: 60 | AO63: 60 | AY63: 60 | BI63: 60
B64: =COUNTA(B4:B63) -> 0 | D64: =SUM(D4:D63) -> 0 | L64: =COUNTA(L4:L63) -> 0 | N64: =SUM(N4:N63) -> 0 | V64: =COUNTA(V4:V63) -> 0 | X64: =SUM(X4:X63) -> 0 | AF64: =COUNTA(AF4:AF63) -> 0 | AH64: =SUM(AH4:AH63) -> 0 | AP64: =COUNTA(AP4:AP63) -> 0 | AR64: =SUM(AR4:AR63) -> 0 | AZ64: =COUNTA(AZ4:AZ63) -> 0 | BB64: =SUM(BB4:BB63) -> 0 | BJ64: =COUNTA(BJ4:BJ63) -> 0 | BL64: =SUM(BL4:BL63) -> 0
B65: Total Bins of Date | D65: Total Weight of Date | L65: Total Bins of Date | N65: Total Weight of Date | V65: Total Bins of Date | X65: Total Weight of Date | AF65: Total Bins of Date | AH65: Total Weight of Date | AP65: Total Bins of Date | AR65: Total Weight of Date | AZ65: Total Bins of Date | BB65: Total Weight of Date | BJ65: Total Bins of Date | BL65: Total Weight of Date

Sheet 1-525
A1: 001-000525-RbstFree WM Block Totes 160/6 lb | F1: Ttl. Tts. | G1: =B64+L64+V64+AF64+AP64+AZ64+BJ64 -> 0 | H1: Ttl. Wt. | I1: =D64+N64+X64+AH64+AR64+BB64+BL64 -> 0 | L1: 001-000525-RbstFree WM Block Totes 160/6 lb | V1: 001-000525-RbstFree WM Block Totes 160/6 lb | AF1: 001-000525-RbstFree WM Block Totes 160/6 lb | AP1: 001-000525-RbstFree WM Block Totes 160/6 lb | AZ1: 001-000525-RbstFree WM Block Totes 160/6 lb | BJ1: 001-000525-RbstFree WM Block Totes 160/6 lb
B2: Date= | H2: Firmness F=Firm S=Soft | I2: Delvicid Used Y/N | L2: Date= | R2: Firmness F=Firm S=Soft | S2: Delvicid Used Y/N | V2: Date= | AB2: Firmness F=Firm S=Soft | AC2: Delvicid Used Y/N | AF2: Date= | AL2: Firmness F=Firm S=Soft | AM2: Delvicid Used Y/N | AP2: Date= | AV2: Firmness F=Firm S=Soft | AW2: Delvicid Used Y/N | AZ2: Date= | BF2: Firmness F=Firm S=Soft | BG2: Delvicid Used Y/N | BJ2: Date= | BP2: Firmness F=Firm S=Soft | BQ2: Delvicid Used Y/N
B3: Tote/ Skid # | C3: Number of Pieces | D3: Bin Weight | E3: Time Started | F3: Temp | G3: Bin Seal Grade | J3: Int. | L3: Tote/ Skid # | M3: Number of Pieces | N3: Bin Weight | O3: Time Started | P3: Temp | Q3: Bin Seal Grade | T3: Int. | V3: Tote/ Skid # | W3: Number of Pieces | X3: Bin Weight | Y3: Time Started | Z3: Temp | AA3: Bin Seal Grade | AD3: Int. | AF3: Tote/ Skid # | AG3: Number of Pieces | AH3: Bin Weight | AI3: Time Started | AJ3: Temp | AK3: Bin Seal Grade | AN3: Int. | AP3: Tote/ Skid # | AQ3: Number of Pieces | AR3: Bin Weight | AS3: Time Started | AT3: Temp | AU3: Bin Seal Grade | AX3: Int. | AZ3: Tote/ Skid # | BA3: Number of Pieces | BB3: Bin Weight | BC3: Time Started | BD3: Temp | BE3: Bin Seal Grade | BH3: Int. | BJ3: Tote/ Skid # | BK3: Number of Pieces | BL3: Bin Weight | BM3: Time Started | BN3: Temp | BO3: Bin Seal Grade | BR3: Int.
A4: 1 | K4: 1 | U4: 1 | AE4: 1 | AO4: 1 | AY4: 1 | BI4: 1
A5: 2 | K5: 2 | U5: 2 | AE5: 2 | AO5: 2 | AY5: 2 | BI5: 2
A6: 3 | K6: 3 | U6: 3 | AE6: 3 | AO6: 3 | AY6: 3 | BI6: 3
A7: 4 | K7: 4 | U7: 4 | AE7: 4 | AO7: 4 | AY7: 4 | BI7: 4
A8: 5 | K8: 5 | U8: 5 | AE8: 5 | AO8: 5 | AY8: 5 | BI8: 5
A9: 6 | K9: 6 | U9: 6 | AE9: 6 | AO9: 6 | AY9: 6 | BI9: 6
A10: 7 | K10: 7 | U10: 7 | AE10: 7 | AO10: 7 | AY10: 7 | BI10: 7
A11: 8 | K11: 8 | U11: 8 | AE11: 8 | AO11: 8 | AY11: 8 | BI11: 8
A12: 9 | K12: 9 | U12: 9 | AE12: 9 | AO12: 9 | AY12: 9 | BI12: 9
A13: 10 | K13: 10 | U13: 10 | AE13: 10 | AO13: 10 | AY13: 10 | BI13: 10
A14: 11 | K14: 11 | U14: 11 | AE14: 11 | AO14: 11 | AY14: 11 | BI14: 11
A15: 12 | K15: 12 | U15: 12 | AE15: 12 | AO15: 12 | AY15: 12 | BI15: 12
... A63: 60 | K63: 60 | U63: 60 | AE63: 60 | AO63: 60 | AY63: 60 | BI63: 60
B64: =COUNTA(B4:B63) -> 0 | D64: =SUM(D4:D63) -> 0 | L64: =COUNTA(L4:L63) -> 0 | N64: =SUM(N4:N63) -> 0 | V64: =COUNTA(V4:V63) -> 0 | X64: =SUM(X4:X63) -> 0 | AF64: =COUNTA(AF4:AF63) -> 0 | AH64: =SUM(AH4:AH63) -> 0 | AP64: =COUNTA(AP4:AP63) -> 0 | AR64: =SUM(AR4:AR63) -> 0 | AZ64: =COUNTA(AZ4:AZ63) -> 0 | BB64: =SUM(BB4:BB63) -> 0 | BJ64: =COUNTA(BJ4:BJ63) -> 0 | BL64: =SUM(BL4:BL63) -> 0
B65: Total Bins of Date | D65: Total Weight of Date | L65: Total Bins of Date | N65: Total Weight of Date | V65: Total Bins of Date | X65: Total Weight of Date | AF65: Total Bins of Date | AH65: Total Weight of Date | AP65: Total Bins of Date | AR65: Total Weight of Date | AZ65: Total Bins of Date | BB65: Total Weight of Date | BJ65: Total Bins of Date | BL65: Total Weight of Date

Sheet 1-528
A1: 001-000528-Nuovo Rbstf PS Block Totes 160/6 lb | F1: Ttl. Tts. | G1: =B64+L64+V64+AF64+AP64+AZ64+BJ64 -> 0 | H1: Ttl. Wt. | I1: =D64+N64+X64+AH64+AR64+BB64+BL64 -> 0 | L1: 001-000528-Nuovo Rbstf PS Block Totes 160/6 lb | V1: 001-000528-Nuovo Rbstf PS Block Totes 160/6 lb | AF1: 001-000528-Nuovo Rbstf PS Block Totes 160/6 lb | AP1: 001-000528-Nuovo Rbstf PS Block Totes 160/6 lb | AZ1: 001-000528-Nuovo Rbstf PS Block Totes 160/6 lb | BJ1: 001-000528-Nuovo Rbstf PS Block Totes 160/6 lb
B2: Date= | H2: Firmness F=Firm S=Soft | I2: Delvicid Used Y/N | L2: Date= | R2: Firmness F=Firm S=Soft | S2: Delvicid Used Y/N | V2: Date= | AB2: Firmness F=Firm S=Soft | AC2: Delvicid Used Y/N | AF2: Date= | AL2: Firmness F=Firm S=Soft | AM2: Delvicid Used Y/N | AP2: Date= | AV2: Firmness F=Firm S=Soft | AW2: Delvicid Used Y/N | AZ2: Date= | BF2: Firmness F=Firm S=Soft | BG2: Delvicid Used Y/N | BJ2: Date= | BP2: Firmness F=Firm S=Soft | BQ2: Delvicid Used Y/N
B3: Tote/ Skid # | C3: Number of Pieces | D3: Bin Weight | E3: Time Started | F3: Temp | G3: Bin Seal Grade | J3: Int. | L3: Tote/ Skid # | M3: Number of Pieces | N3: Bin Weight | O3: Time Started | P3: Temp | Q3: Bin Seal Grade | T3: Int. | V3: Tote/ Skid # | W3: Number of Pieces | X3: Bin Weight | Y3: Time Started | Z3: Temp | AA3: Bin Seal Grade | AD3: Int. | AF3: Tote/ Skid # | AG3: Number of Pieces | AH3: Bin Weight | AI3: Time Started | AJ3: Temp | AK3: Bin Seal Grade | AN3: Int. | AP3: Tote/ Skid # | AQ3: Number of Pieces | AR3: Bin Weight | AS3: Time Started | AT3: Temp | AU3: Bin Seal Grade | AX3: Int. | AZ3: Tote/ Skid # | BA3: Number of Pieces | BB3: Bin Weight | BC3: Time Started | BD3: Temp | BE3: Bin Seal Grade | BH3: Int. | BJ3: Tote/ Skid # | BK3: Number of Pieces | BL3: Bin Weight | BM3: Time Started | BN3: Temp | BO3: Bin Seal Grade | BR3: Int.
A4: 1 | K4: 1 | U4: 1 | AE4: 1 | AO4: 1 | AY4: 1 | BI4: 1
A5: 2 | K5: 2 | U5: 2 | AE5: 2 | AO5: 2 | AY5: 2 | BI5: 2
A6: 3 | K6: 3 | U6: 3 | AE6: 3 | AO6: 3 | AY6: 3 | BI6: 3
A7: 4 | K7: 4 | U7: 4 | AE7: 4 | AO7: 4 | AY7: 4 | BI7: 4
A8: 5 | K8: 5 | U8: 5 | AE8: 5 | AO8: 5 | AY8: 5 | BI8: 5
A9: 6 | K9: 6 | U9: 6 | AE9: 6 | AO9: 6 | AY9: 6 | BI9: 6
A10: 7 | K10: 7 | U10: 7 | AE10: 7 | AO10: 7 | AY10: 7 | BI10: 7
A11: 8 | K11: 8 | U11: 8 | AE11: 8 | AO11: 8 | AY11: 8 | BI11: 8
A12: 9 | K12: 9 | U12: 9 | AE12: 9 | AO12: 9 | AY12: 9 | BI12: 9
A13: 10 | K13: 10 | U13: 10 | AE13: 10 | AO13: 10 | AY13: 10 | BI13: 10
A14: 11 | K14: 11 | U14: 11 | AE14: 11 | AO14: 11 | AY14: 11 | BI14: 11
A15: 12 | K15: 12 | U15: 12 | AE15: 12 | AO15: 12 | AY15: 12 | BI15: 12
... A63: 60 | K63: 60 | U63: 60 | AE63: 60 | AO63: 60 | AY63: 60 | BI63: 60
B64: =COUNTA(B4:B63) -> 0 | D64: =SUM(D4:D63) -> 0 | L64: =COUNTA(L4:L63) -> 0 | N64: =SUM(N4:N63) -> 0 | V64: =COUNTA(V4:V63) -> 0 | X64: =SUM(X4:X63) -> 0 | AF64: =COUNTA(AF4:AF63) -> 0 | AH64: =SUM(AH4:AH63) -> 0 | AP64: =COUNTA(AP4:AP63) -> 0 | AR64: =SUM(AR4:AR63) -> 0 | AZ64: =COUNTA(AZ4:AZ63) -> 0 | BB64: =SUM(BB4:BB63) -> 0 | BJ64: =COUNTA(BJ4:BJ63) -> 0 | BL64: =SUM(BL4:BL63) -> 0
B65: Total Bins of Date | D65: Total Weight of Date | L65: Total Bins of Date | N65: Total Weight of Date | V65: Total Bins of Date | X65: Total Weight of Date | AF65: Total Bins of Date | AH65: Total Weight of Date | AP65: Total Bins of Date | AR65: Total Weight of Date | AZ65: Total Bins of Date | BB65: Total Weight of Date | BJ65: Total Bins of Date | BL65: Total Weight of Date

Sheet 1-705
A1: 001-000705--PS PZ Block Totes 160/6 lb | F1: Ttl. Tts. | G1: =B64+L64+V64+AF64+AP64+AZ64+BJ64 -> 0 | H1: Ttl. Wt. | I1: =D64+N64+X64+AH64+AR64+BB64+BL64 -> 0 | L1: 001-000705--PS PZ Block Totes 160/6 lb | V1: 001-000705--PS PZ Block Totes 160/6 lb | AF1: 001-000705--PS PZ Block Totes 160/6 lb | AP1: 001-000705--PS PZ Block Totes 160/6 lb | AZ1: 001-000705--PS PZ Block Totes 160/6 lb | BJ1: 001-000705--PS PZ Block Totes 160/6 lb
B2: Date= | H2: Firmness F=Firm S=Soft | I2: Delvicid Used Y/N | L2: Date= | R2: Firmness F=Firm S=Soft | S2: Delvicid Used Y/N | V2: Date= | AB2: Firmness F=Firm S=Soft | AC2: Delvicid Used Y/N | AF2: Date= | AL2: Firmness F=Firm S=Soft | AM2: Delvicid Used Y/N | AP2: Date= | AV2: Firmness F=Firm S=Soft | AW2: Delvicid Used Y/N | AZ2: Date= | BF2: Firmness F=Firm S=Soft | BG2: Delvicid Used Y/N | BJ2: Date= | BP2: Firmness F=Firm S=Soft | BQ2: Delvicid Used Y/N
B3: Tote/ Skid # | C3: Number of Pieces | D3: Bin Weight | E3: Time Started | F3: Temp | G3: Bin Seal Grade | J3: Int. | L3: Tote/ Skid # | M3: Number of Pieces | N3: Bin Weight | O3: Time Started | P3: Temp | Q3: Bin Seal Grade | T3: Int. | V3: Tote/ Skid # | W3: Number of Pieces | X3: Bin Weight | Y3: Time Started | Z3: Temp | AA3: Bin Seal Grade | AD3: Int. | AF3: Tote/ Skid # | AG3: Number of Pieces | AH3: Bin Weight | AI3: Time Started | AJ3: Temp | AK3: Bin Seal Grade | AN3: Int. | AP3: Tote/ Skid # | AQ3: Number of Pieces | AR3: Bin Weight | AS3: Time Started | AT3: Temp | AU3: Bin Seal Grade | AX3: Int. | AZ3: Tote/ Skid # | BA3: Number of Pieces | BB3: Bin Weight | BC3: Time Started | BD3: Temp | BE3: Bin Seal Grade | BH3: Int. | BJ3: Tote/ Skid # | BK3: Number of Pieces | BL3: Bin Weight | BM3: Time Started | BN3: Temp | BO3: Bin Seal Grade | BR3: Int.
A4: 1 | K4: 1 | U4: 1 | AE4: 1 | AO4: 1 | AY4: 1 | BI4: 1
A5: 2 | K5: 2 | U5: 2 | AE5: 2 | AO5: 2 | AY5: 2 | BI5: 2
A6: 3 | K6: 3 | U6: 3 | AE6: 3 | AO6: 3 | AY6: 3 | BI6: 3
A7: 4 | K7: 4 | U7: 4 | AE7: 4 | AO7: 4 | AY7: 4 | BI7: 4
A8: 5 | K8: 5 | U8: 5 | AE8: 5 | AO8: 5 | AY8: 5 | BI8: 5
A9: 6 | K9: 6 | U9: 6 | AE9: 6 | AO9: 6 | AY9: 6 | BI9: 6
A10: 7 | K10: 7 | U10: 7 | AE10: 7 | AO10: 7 | AY10: 7 | BI10: 7
A11: 8 | K11: 8 | U11: 8 | AE11: 8 | AO11: 8 | AY11: 8 | BI11: 8
A12: 9 | K12: 9 | U12: 9 | AE12: 9 | AO12: 9 | AY12: 9 | BI12: 9
A13: 10 | K13: 10 | U13: 10 | AE13: 10 | AO13: 10 | AY13: 10 | BI13: 10
A14: 11 | K14: 11 | U14: 11 | AE14: 11 | AO14: 11 | AY14: 11 | BI14: 11
A15: 12 | K15: 12 | U15: 12 | AE15: 12 | AO15: 12 | AY15: 12 | BI15: 12
... A63: 60 | K63: 60 | U63: 60 | AE63: 60 | AO63: 60 | AY63: 60 | BI63: 60
B64: =COUNTA(B4:B63) -> 0 | D64: =SUM(D4:D63) -> 0 | L64: =COUNTA(L4:L63) -> 0 | N64: =SUM(N4:N63) -> 0 | V64: =COUNTA(V4:V63) -> 0 | X64: =SUM(X4:X63) -> 0 | AF64: =COUNTA(AF4:AF63) -> 0 | AH64: =SUM(AH4:AH63) -> 0 | AP64: =COUNTA(AP4:AP63) -> 0 | AR64: =SUM(AR4:AR63) -> 0 | AZ64: =COUNTA(AZ4:AZ63) -> 0 | BB64: =SUM(BB4:BB63) -> 0 | BJ64: =COUNTA(BJ4:BJ63) -> 0 | BL64: =SUM(BL4:BL63) -> 0
B65: Total Bins of Date | D65: Total Weight of Date | L65: Total Bins of Date | N65: Total Weight of Date | V65: Total Bins of Date | X65: Total Weight of Date | AF65: Total Bins of Date | AH65: Total Weight of Date | AP65: Total Bins of Date | AR65: Total Weight of Date | AZ65: Total Bins of Date | BB65: Total Weight of Date | BJ65: Total Bins of Date | BL65: Total Weight of Date

Sheet PS Purchased
A1: 008-000005-Part Skim Block Totes 96/20 lb | F1: Ttl. Tts. | G1: =B64+L64+V64+AF64+AP64+AZ64+BJ64 -> 0 | H1: Ttl. Wt. | I1: =D64+N64+X64+AH64+AR64+BB64+BL64 -> 0 | L1: 008-000005-Part Skim Block Totes 96/20 lb | V1: 008-000005-Part Skim Block Totes 96/20 lb | AF1: 008-000005-Part Skim Block Totes 96/20 lb | AP1: 008-000005-Part Skim Block Totes 96/20 lb | AZ1: 008-000005-Part Skim Block Totes 96/20 lb | BJ1: 008-000005-Part Skim Block Totes 96/20 lb
B2: Date= | H2: Firmness F=Firm S=Soft | I2: Delvicid Used Y/N | L2: Date= | R2: Firmness F=Firm S=Soft | S2: Delvicid Used Y/N | V2: Date= | AB2: Firmness F=Firm S=Soft | AC2: Delvicid Used Y/N | AF2: Date= | AL2: Firmness F=Firm S=Soft | AM2: Delvicid Used Y/N | AP2: Date= | AV2: Firmness F=Firm S=Soft | AW2: Delvicid Used Y/N | AZ2: Date= | BF2: Firmness F=Firm S=Soft | BG2: Delvicid Used Y/N | BJ2: Date= | BP2: Firmness F=Firm S=Soft | BQ2: Delvicid Used Y/N
B3: Tote/ Skid # | C3: Number of Pieces | D3: Bin Weight | E3: Time Started | F3: Temp | G3: Bin Seal Grade | J3: Int. | L3: Tote/ Skid # | M3: Number of Pieces | N3: Bin Weight | O3: Time Started | P3: Temp | Q3: Bin Seal Grade | T3: Int. | V3: Tote/ Skid # | W3: Number of Pieces | X3: Bin Weight | Y3: Time Started | Z3: Temp | AA3: Bin Seal Grade | AD3: Int. | AF3: Tote/ Skid # | AG3: Number of Pieces | AH3: Bin Weight | AI3: Time Started | AJ3: Temp | AK3: Bin Seal Grade | AN3: Int. | AP3: Tote/ Skid # | AQ3: Number of Pieces | AR3: Bin Weight | AS3: Time Started | AT3: Temp | AU3: Bin Seal Grade | AX3: Int. | AZ3: Tote/ Skid # | BA3: Number of Pieces | BB3: Bin Weight | BC3: Time Started | BD3: Temp | BE3: Bin Seal Grade | BH3: Int. | BJ3: Tote/ Skid # | BK3: Number of Pieces | BL3: Bin Weight | BM3: Time Started | BN3: Temp | BO3: Bin Seal Grade | BR3: Int.
A4: 1 | K4: 1 | U4: 1 | AE4: 1 | AO4: 1 | AY4: 1 | BI4: 1
A5: 2 | K5: 2 | U5: 2 | AE5: 2 | AO5: 2 | AY5: 2 | BI5: 2
A6: 3 | K6: 3 | U6: 3 | AE6: 3 | AO6: 3 | AY6: 3 | BI6: 3
A7: 4 | K7: 4 | U7: 4 | AE7: 4 | AO7: 4 | AY7: 4 | BI7: 4
A8: 5 | K8: 5 | U8: 5 | AE8: 5 | AO8: 5 | AY8: 5 | BI8: 5
A9: 6 | K9: 6 | U9: 6 | AE9: 6 | AO9: 6 | AY9: 6 | BI9: 6
A10: 7 | K10: 7 | U10: 7 | AE10: 7 | AO10: 7 | AY10: 7 | BI10: 7
A11: 8 | K11: 8 | U11: 8 | AE11: 8 | AO11: 8 | AY11: 8 | BI11: 8
A12: 9 | K12: 9 | U12: 9 | AE12: 9 | AO12: 9 | AY12: 9 | BI12: 9
A13: 10 | K13: 10 | U13: 10 | AE13: 10 | AO13: 10 | AY13: 10 | BI13: 10
A14: 11 | K14: 11 | U14: 11 | AE14: 11 | AO14: 11 | AY14: 11 | BI14: 11
A15: 12 | K15: 12 | U15: 12 | AE15: 12 | AO15: 12 | AY15: 12 | BI15: 12
... A63: 60 | K63: 60 | U63: 60 | AE63: 60 | AO63: 60 | AY63: 60 | BI63: 60
B64: =COUNTA(B4:B63) -> 0 | D64: =SUM(D4:D63) -> 0 | L64: =COUNTA(L4:L63) -> 0 | N64: =SUM(N4:N63) -> 0 | V64: =COUNTA(V4:V63) -> 0 | X64: =SUM(X4:X63) -> 0 | AF64: =COUNTA(AF4:AF63) -> 0 | AH64: =SUM(AH4:AH63) -> 0 | AP64: =COUNTA(AP4:AP63) -> 0 | AR64: =SUM(AR4:AR63) -> 0 | AZ64: =COUNTA(AZ4:AZ63) -> 0 | BB64: =SUM(BB4:BB63) -> 0 | BJ64: =COUNTA(BJ4:BJ63) -> 0 | BL64: =SUM(BL4:BL63) -> 0
B65: Total Bins of Date | D65: Total Weight of Date | L65: Total Bins of Date | N65: Total Weight of Date | V65: Total Bins of Date | X65: Total Weight of Date | AF65: Total Bins of Date | AH65: Total Weight of Date | AP65: Total Bins of Date | AR65: Total Weight of Date | AZ65: Total Bins of Date | BB65: Total Weight of Date | BJ65: Total Bins of Date | BL65: Total Weight of Date

Sheet WM Purchased
A1: 008-000021--WM Block Totes 96/20 lb | F1: Ttl. Tts. | G1: =B64+L64+V64+AF64+AP64+AZ64+BJ64 -> 0 | H1: Ttl. Wt. | I1: =D64+N64+X64+AH64+AR64+BB64+BL64 -> 0 | L1: 008-000021--WM Block Totes 96/20 lb | V1: 008-000021--WM Block Totes 96/20 lb | AF1: 008-000021--WM Block Totes 96/20 lb | AP1: 008-000021--WM Block Totes 96/20 lb | AZ1: 008-000021--WM Block Totes 96/20 lb | BJ1: 008-000021--WM Block Totes 96/20 lb
B2: Date= | H2: Firmness F=Firm S=Soft | I2: Delvicid Used Y/N | L2: Date= | R2: Firmness F=Firm S=Soft | S2: Delvicid Used Y/N | V2: Date= | AB2: Firmness F=Firm S=Soft | AC2: Delvicid Used Y/N | AF2: Date= | AL2: Firmness F=Firm S=Soft | AM2: Delvicid Used Y/N | AP2: Date= | AV2: Firmness F=Firm S=Soft | AW2: Delvicid Used Y/N | AZ2: Date= | BF2: Firmness F=Firm S=Soft | BG2: Delvicid Used Y/N | BJ2: Date= | BP2: Firmness F=Firm S=Soft | BQ2: Delvicid Used Y/N
B3: Tote/ Skid # | C3: Number of Pieces | D3: Bin Weight | E3: Time Started | F3: Temp | G3: Bin Seal Grade | J3: Int. | L3: Tote/ Skid # | M3: Number of Pieces | N3: Bin Weight | O3: Time Started | P3: Temp | Q3: Bin Seal Grade | T3: Int. | V3: Tote/ Skid # | W3: Number of Pieces | X3: Bin Weight | Y3: Time Started | Z3: Temp | AA3: Bin Seal Grade | AD3: Int. | AF3: Tote/ Skid # | AG3: Number of Pieces | AH3: Bin Weight | AI3: Time Started | AJ3: Temp | AK3: Bin Seal Grade | AN3: Int. | AP3: Tote/ Skid # | AQ3: Number of Pieces | AR3: Bin Weight | AS3: Time Started | AT3: Temp | AU3: Bin Seal Grade | AX3: Int. | AZ3: Tote/ Skid # | BA3: Number of Pieces | BB3: Bin Weight | BC3: Time Started | BD3: Temp | BE3: Bin Seal Grade | BH3: Int. | BJ3: Tote/ Skid # | BK3: Number of Pieces | BL3: Bin Weight | BM3: Time Started | BN3: Temp | BO3: Bin Seal Grade | BR3: Int.
A4: 1 | K4: 1 | U4: 1 | AE4: 1 | AO4: 1 | AY4: 1 | BI4: 1
A5: 2 | K5: 2 | U5: 2 | AE5: 2 | AO5: 2 | AY5: 2 | BI5: 2
A6: 3 | K6: 3 | U6: 3 | AE6: 3 | AO6: 3 | AY6: 3 | BI6: 3
A7: 4 | K7: 4 | U7: 4 | AE7: 4 | AO7: 4 | AY7: 4 | BI7: 4
A8: 5 | K8: 5 | U8: 5 | AE8: 5 | AO8: 5 | AY8: 5 | BI8: 5
A9: 6 | K9: 6 | U9: 6 | AE9: 6 | AO9: 6 | AY9: 6 | BI9: 6
A10: 7 | K10: 7 | U10: 7 | AE10: 7 | AO10: 7 | AY10: 7 | BI10: 7
A11: 8 | K11: 8 | U11: 8 | AE11: 8 | AO11: 8 | AY11: 8 | BI11: 8
A12: 9 | K12: 9 | U12: 9 | AE12: 9 | AO12: 9 | AY12: 9 | BI12: 9
A13: 10 | K13: 10 | U13: 10 | AE13: 10 | AO13: 10 | AY13: 10 | BI13: 10
A14: 11 | K14: 11 | U14: 11 | AE14: 11 | AO14: 11 | AY14: 11 | BI14: 11
A15: 12 | K15: 12 | U15: 12 | AE15: 12 | AO15: 12 | AY15: 12 | BI15: 12
... A63: 60 | K63: 60 | U63: 60 | AE63: 60 | AO63: 60 | AY63: 60 | BI63: 60
B64: =COUNTA(B4:B63) -> 0 | D64: =SUM(D4:D63) -> 0 | L64: =COUNTA(L4:L63) -> 0 | N64: =SUM(N4:N63) -> 0 | V64: =COUNTA(V4:V63) -> 0 | X64: =SUM(X4:X63) -> 0 | AF64: =COUNTA(AF4:AF63) -> 0 | AH64: =SUM(AH4:AH63) -> 0 | AP64: =COUNTA(AP4:AP63) -> 0 | AR64: =SUM(AR4:AR63) -> 0 | AZ64: =COUNTA(AZ4:AZ63) -> 0 | BB64: =SUM(BB4:BB63) -> 0 | BJ64: =COUNTA(BJ4:BJ63) -> 0 | BL64: =SUM(BL4:BL63) -> 0
B65: Total Bins of Date | D65: Total Weight of Date | L65: Total Bins of Date | N65: Total Weight of Date | V65: Total Bins of Date | X65: Total Weight of Date | AF65: Total Bins of Date | AH65: Total Weight of Date | AP65: Total Bins of Date | AR65: Total Weight of Date | AZ65: Total Bins of Date | BB65: Total Weight of Date | BJ65: Total Bins of Date | BL65: Total Weight of Date

Sheet Asiago40#
A1: 008-000001--Asiago Blocks 40 lb RW | D1: Ttl. Tts. | E1: =F64+N64+V64+AD64+AL64+AT64+BB64+BJ64+BR64+BZ64+CH64+CP64 -> 0 | F1: Ttl. Wt. | G1: =B64+J64+R64+Z64+AH64+AP64+AX64+BF64+BN64+BV64+CD64+CL64 -> 0 | I1: 008-000001--Asiago Blocks 40 lb RW | Q1: 008-000001--Asiago Blocks 40 lb RW | Y1: 008-000001--Asiago Blocks 40 lb RW | AG1: 008-000001--Asiago Blocks 40 lb RW | AO1: 008-000001--Asiago Blocks 40 lb RW | AW1: 008-000001--Asiago Blocks 40 lb RW | BE1: 008-000001--Asiago Blocks 40 lb RW | BM1: 008-000001--Asiago Blocks 40 lb RW | BU1: 008-000001--Asiago Blocks 40 lb RW | CC1: 008-000001--Asiago Blocks 40 lb RW | CK1: 008-000001--Asiago Blocks 40 lb RW
B2: Date= | F2: Firmness F=Firm S=Soft | G2: Delvicid Used Y/N | J2: Date= | N2: Firmness F=Firm S=Soft | O2: Delvicid Used Y/N | R2: Date= | V2: Firmness F=Firm S=Soft | W2: Delvicid Used Y/N | Z2: Date= | AD2: Firmness F=Firm S=Soft | AE2: Delvicid Used Y/N | AH2: Date= | AL2: Firmness F=Firm S=Soft | AM2: Delvicid Used Y/N | AP2: Date= | AT2: Firmness F=Firm S=Soft | AU2: Delvicid Used Y/N | AX2: Date= | BB2: Firmness F=Firm S=Soft | BC2: Delvicid Used Y/N | BF2: Date= | BJ2: Firmness F=Firm S=Soft | BK2: Delvicid Used Y/N | BN2: Date= | BR2: Firmness F=Firm S=Soft | BS2: Delvicid Used Y/N | BV2: Date= | BZ2: Firmness F=Firm S=Soft | CA2: Delvicid Used Y/N | CD2: Date= | CH2: Firmness F=Firm S=Soft | CI2: Delvicid Used Y/N | CL2: Date= | CP2: Firmness F=Firm S=Soft | CQ2: Delvicid Used Y/N
B3: Qty. of Blocks | C3: Time Started | D3: Temp | E3: Bin Seal Grade | H3: Int. | J3: Qty. of Blocks | K3: Time Started | L3: Temp | M3: Bin Seal Grade | P3: Int. | R3: Qty. of Blocks | S3: Time Started | T3: Temp | U3: Bin Seal Grade | X3: Int. | Z3: Qty. of Blocks | AA3: Time Started | AB3: Temp | AC3: Bin Seal Grade | AF3: Int. | AH3: Qty. of Blocks | AI3: Time Started | AJ3: Temp | AK3: Bin Seal Grade | AN3: Int. | AP3: Qty. of Blocks | AQ3: Time Started | AR3: Temp | AS3: Bin Seal Grade | AV3: Int. | AX3: Qty. of Blocks | AY3: Time Started | AZ3: Temp | BA3: Bin Seal Grade | BD3: Int. | BF3: Qty. of Blocks | BG3: Time Started | BH3: Temp | BI3: Bin Seal Grade | BL3: Int. | BN3: Qty. of Blocks | BO3: Time Started | BP3: Temp | BQ3: Bin Seal Grade | BT3: Int. | BV3: Qty. of Blocks | BW3: Time Started | BX3: Temp | BY3: Bin Seal Grade | CB3: Int. | CD3: Qty. of Blocks | CE3: Time Started | CF3: Temp | CG3: Bin Seal Grade | CJ3: Int. | CL3: Qty. of Blocks | CM3: Time Started | CN3: Temp | CO3: Bin Seal Grade | CR3: Int.
A4: 1 | I4: 1 | Q4: 1 | Y4: 1 | AG4: 1 | AO4: 1 | AW4: 1 | BE4: 1 | BM4: 1 | BU4: 1 | CC4: 1 | CK4: 1
A5: 2 | I5: 2 | Q5: 2 | Y5: 2 | AG5: 2 | AO5: 2 | AW5: 2 | BE5: 2 | BM5: 2 | BU5: 2 | CC5: 2 | CK5: 2
A6: 3 | I6: 3 | Q6: 3 | Y6: 3 | AG6: 3 | AO6: 3 | AW6: 3 | BE6: 3 | BM6: 3 | BU6: 3 | CC6: 3 | CK6: 3
A7: 4 | I7: 4 | Q7: 4 | Y7: 4 | AG7: 4 | AO7: 4 | AW7: 4 | BE7: 4 | BM7: 4 | BU7: 4 | CC7: 4 | CK7: 4
A8: 5 | I8: 5 | Q8: 5 | Y8: 5 | AG8: 5 | AO8: 5 | AW8: 5 | BE8: 5 | BM8: 5 | BU8: 5 | CC8: 5 | CK8: 5
A9: 6 | I9: 6 | Q9: 6 | Y9: 6 | AG9: 6 | AO9: 6 | AW9: 6 | BE9: 6 | BM9: 6 | BU9: 6 | CC9: 6 | CK9: 6
A10: 7 | I10: 7 | Q10: 7 | Y10: 7 | AG10: 7 | AO10: 7 | AW10: 7 | BE10: 7 | BM10: 7 | BU10: 7 | CC10: 7 | CK10: 7
A11: 8 | I11: 8 | Q11: 8 | Y11: 8 | AG11: 8 | AO11: 8 | AW11: 8 | BE11: 8 | BM11: 8 | BU11: 8 | CC11: 8 | CK11: 8
A12: 9 | I12: 9 | Q12: 9 | Y12: 9 | AG12: 9 | AO12: 9 | AW12: 9 | BE12: 9 | BM12: 9 | BU12: 9 | CC12: 9 | CK12: 9
A13: 10 | I13: 10 | Q13: 10 | Y13: 10 | AG13: 10 | AO13: 10 | AW13: 10 | BE13: 10 | BM13: 10 | BU13: 10 | CC13: 10 | CK13: 10
A14: 11 | I14: 11 | Q14: 11 | Y14: 11 | AG14: 11 | AO14: 11 | AW14: 11 | BE14: 11 | BM14: 11 | BU14: 11 | CC14: 11 | CK14: 11
A15: 12 | I15: 12 | Q15: 12 | Y15: 12 | AG15: 12 | AO15: 12 | AW15: 12 | BE15: 12 | BM15: 12 | BU15: 12 | CC15: 12 | CK15: 12
... A63: 60 | I63: 60 | Q63: 60 | Y63: 60 | AG63: 60 | AO63: 60 | AW63: 60 | BE63: 60 | BM63: 60 | BU63: 60 | CC63: 60 | CK63: 60
B64: =SUM(B4:B63)*40 -> 0 | F64: =SUM(B4:B63) -> 0 | J64: =SUM(J4:J63)*40 -> 0 | N64: =SUM(J4:J63) -> 0 | R64: =SUM(R4:R63)*40 -> 0 | V64: =SUM(R4:R63) -> 0 | Z64: =SUM(Z4:Z63)*40 -> 0 | AD64: =SUM(Z4:Z63) -> 0 | AH64: =SUM(AH4:AH63)*40 -> 0 | AL64: =SUM(AH4:AH63) -> 0 | AP64: =SUM(AP4:AP63)*40 -> 0 | AT64: =SUM(AP4:AP63) -> 0 | AX64: =SUM(AX4:AX63)*40 -> 0 | BB64: =SUM(AX4:AX63) -> 0 | BF64: =SUM(BF4:BF63)*40 -> 0 | BJ64: =SUM(BF4:BF63) -> 0 | BN64: =SUM(BN4:BN63)*40 -> 0 | BR64: =SUM(BN4:BN63) -> 0 | BV64: =SUM(BV4:BV63)*40 -> 0 | BZ64: =SUM(BV4:BV63) -> 0 | CD64: =SUM(CD4:CD63)*40 -> 0 | CH64: =SUM(CD4:CD63) -> 0 | CL64: =SUM(CL4:CL63)*40 -> 0 | CP64: =SUM(CL4:CL63) -> 0
B65: Total Weight of Date | F65: Total Bins of Date | J65: Total Weight of Date | N65: Total Bins of Date | R65: Total Weight of Date | V65: Total Bins of Date | Z65: Total Weight of Date | AD65: Total Bins of Date | AH65: Total Weight of Date | AL65: Total Bins of Date | AP65: Total Weight of Date | AT65: Total Bins of Date | AX65: Total Weight of Date | BB65: Total Bins of Date | BF65: Total Weight of Date | BJ65: Total Bins of Date | BN65: Total Weight of Date | BR65: Total Bins of Date | BV65: Total Weight of Date | BZ65: Total Bins of Date | CD65: Total Weight of Date | CH65: Total Bins of Date | CL65: Total Weight of Date | CP65: Total Bins of Date

Sheet Ched40#
A1: 008-000002--Ched Blocks 40 lb RW | D1: Ttl. Tts. | E1: =F64+N64+V64+AD64+AL64+AT64+BB64+BJ64+BR64+BZ64+CH64+CP64 -> 0 | F1: Ttl. Wt. | G1: =B64+J64+R64+Z64+AH64+AP64+AX64+BF64+BN64+BV64+CD64+CL64 -> 0 | I1: 008-000002--Ched Blocks 40 lb RW | Q1: 008-000002--Ched Blocks 40 lb RW | Y1: 008-000002--Ched Blocks 40 lb RW | AG1: 008-000002--Ched Blocks 40 lb RW | AO1: 008-000002--Ched Blocks 40 lb RW | AW1: 008-000002--Ched Blocks 40 lb RW | BE1: 008-000002--Ched Blocks 40 lb RW | BM1: 008-000002--Ched Blocks 40 lb RW | BU1: 008-000002--Ched Blocks 40 lb RW | CC1: 008-000002--Ched Blocks 40 lb RW | CK1: 008-000002--Ched Blocks 40 lb RW
B2: Date= | F2: Firmness F=Firm S=Soft | G2: Delvicid Used Y/N | J2: Date= | N2: Firmness F=Firm S=Soft | O2: Delvicid Used Y/N | R2: Date= | V2: Firmness F=Firm S=Soft | W2: Delvicid Used Y/N | Z2: Date= | AD2: Firmness F=Firm S=Soft | AE2: Delvicid Used Y/N | AH2: Date= | AL2: Firmness F=Firm S=Soft | AM2: Delvicid Used Y/N | AP2: Date= | AT2: Firmness F=Firm S=Soft | AU2: Delvicid Used Y/N | AX2: Date= | BB2: Firmness F=Firm S=Soft | BC2: Delvicid Used Y/N | BF2: Date= | BJ2: Firmness F=Firm S=Soft | BK2: Delvicid Used Y/N | BN2: Date= | BR2: Firmness F=Firm S=Soft | BS2: Delvicid Used Y/N | BV2: Date= | BZ2: Firmness F=Firm S=Soft | CA2: Delvicid Used Y/N | CD2: Date= | CH2: Firmness F=Firm S=Soft | CI2: Delvicid Used Y/N | CL2: Date= | CP2: Firmness F=Firm S=Soft | CQ2: Delvicid Used Y/N
B3: Qty. of Blocks | C3: Time Started | D3: Temp | E3: Bin Seal Grade | H3: Int. | J3: Qty. of Blocks | K3: Time Started | L3: Temp | M3: Bin Seal Grade | P3: Int. | R3: Qty. of Blocks | S3: Time Started | T3: Temp | U3: Bin Seal Grade | X3: Int. | Z3: Qty. of Blocks | AA3: Time Started | AB3: Temp | AC3: Bin Seal Grade | AF3: Int. | AH3: Qty. of Blocks | AI3: Time Started | AJ3: Temp | AK3: Bin Seal Grade | AN3: Int. | AP3: Qty. of Blocks | AQ3: Time Started | AR3: Temp | AS3: Bin Seal Grade | AV3: Int. | AX3: Qty. of Blocks | AY3: Time Started | AZ3: Temp | BA3: Bin Seal Grade | BD3: Int. | BF3: Qty. of Blocks | BG3: Time Started | BH3: Temp | BI3: Bin Seal Grade | BL3: Int. | BN3: Qty. of Blocks | BO3: Time Started | BP3: Temp | BQ3: Bin Seal Grade | BT3: Int. | BV3: Qty. of Blocks | BW3: Time Started | BX3: Temp | BY3: Bin Seal Grade | CB3: Int. | CD3: Qty. of Blocks | CE3: Time Started | CF3: Temp | CG3: Bin Seal Grade | CJ3: Int. | CL3: Qty. of Blocks | CM3: Time Started | CN3: Temp | CO3: Bin Seal Grade | CR3: Int.
A4: 1 | I4: 1 | Q4: 1 | Y4: 1 | AG4: 1 | AO4: 1 | AW4: 1 | BE4: 1 | BM4: 1 | BU4: 1 | CC4: 1 | CK4: 1
A5: 2 | I5: 2 | Q5: 2 | Y5: 2 | AG5: 2 | AO5: 2 | AW5: 2 | BE5: 2 | BM5: 2 | BU5: 2 | CC5: 2 | CK5: 2
A6: 3 | I6: 3 | Q6: 3 | Y6: 3 | AG6: 3 | AO6: 3 | AW6: 3 | BE6: 3 | BM6: 3 | BU6: 3 | CC6: 3 | CK6: 3
A7: 4 | I7: 4 | Q7: 4 | Y7: 4 | AG7: 4 | AO7: 4 | AW7: 4 | BE7: 4 | BM7: 4 | BU7: 4 | CC7: 4 | CK7: 4
A8: 5 | I8: 5 | Q8: 5 | Y8: 5 | AG8: 5 | AO8: 5 | AW8: 5 | BE8: 5 | BM8: 5 | BU8: 5 | CC8: 5 | CK8: 5
A9: 6 | I9: 6 | Q9: 6 | Y9: 6 | AG9: 6 | AO9: 6 | AW9: 6 | BE9: 6 | BM9: 6 | BU9: 6 | CC9: 6 | CK9: 6
A10: 7 | I10: 7 | Q10: 7 | Y10: 7 | AG10: 7 | AO10: 7 | AW10: 7 | BE10: 7 | BM10: 7 | BU10: 7 | CC10: 7 | CK10: 7
A11: 8 | I11: 8 | Q11: 8 | Y11: 8 | AG11: 8 | AO11: 8 | AW11: 8 | BE11: 8 | BM11: 8 | BU11: 8 | CC11: 8 | CK11: 8
A12: 9 | I12: 9 | Q12: 9 | Y12: 9 | AG12: 9 | AO12: 9 | AW12: 9 | BE12: 9 | BM12: 9 | BU12: 9 | CC12: 9 | CK12: 9
A13: 10 | I13: 10 | Q13: 10 | Y13: 10 | AG13: 10 | AO13: 10 | AW13: 10 | BE13: 10 | BM13: 10 | BU13: 10 | CC13: 10 | CK13: 10
A14: 11 | I14: 11 | Q14: 11 | Y14: 11 | AG14: 11 | AO14: 11 | AW14: 11 | BE14: 11 | BM14: 11 | BU14: 11 | CC14: 11 | CK14: 11
A15: 12 | I15: 12 | Q15: 12 | Y15: 12 | AG15: 12 | AO15: 12 | AW15: 12 | BE15: 12 | BM15: 12 | BU15: 12 | CC15: 12 | CK15: 12
... A63: 60 | I63: 60 | Q63: 60 | Y63: 60 | AG63: 60 | AO63: 60 | AW63: 60 | BE63: 60 | BM63: 60 | BU63: 60 | CC63: 60 | CK63: 60
B64: =SUM(B4:B63)*40 -> 0 | F64: =SUM(B4:B63) -> 0 | J64: =SUM(J4:J63)*40 -> 0 | N64: =SUM(J4:J63) -> 0 | R64: =SUM(R4:R63)*40 -> 0 | V64: =SUM(R4:R63) -> 0 | Z64: =SUM(Z4:Z63)*40 -> 0 | AD64: =SUM(Z4:Z63) -> 0 | AH64: =SUM(AH4:AH63)*40 -> 0 | AL64: =SUM(AH4:AH63) -> 0 | AP64: =SUM(AP4:AP63)*40 -> 0 | AT64: =SUM(AP4:AP63) -> 0 | AX64: =SUM(AX4:AX63)*40 -> 0 | BB64: =SUM(AX4:AX63) -> 0 | BF64: =SUM(BF4:BF63)*40 -> 0 | BJ64: =SUM(BF4:BF63) -> 0 | BN64: =SUM(BN4:BN63)*40 -> 0 | BR64: =SUM(BN4:BN63) -> 0 | BV64: =SUM(BV4:BV63)*40 -> 0 | BZ64: =SUM(BV4:BV63) -> 0 | CD64: =SUM(CD4:CD63)*40 -> 0 | CH64: =SUM(CD4:CD63) -> 0 | CL64: =SUM(CL4:CL63)*40 -> 0 | CP64: =SUM(CL4:CL63) -> 0
B65: Total Weight of Date | F65: Total Bins of Date | J65: Total Weight of Date | N65: Total Bins of Date | R65: Total Weight of Date | V65: Total Bins of Date | Z65: Total Weight of Date | AD65: Total Bins of Date | AH65: Total Weight of Date | AL65: Total Bins of Date | AP65: Total Weight of Date | AT65: Total Bins of Date | AX65: Total Weight of Date | BB65: Total Bins of Date | BF65: Total Weight of Date | BJ65: Total Bins of Date | BN65: Total Weight of Date | BR65: Total Bins of Date | BV65: Total Weight of Date | BZ65: Total Bins of Date | CD65: Total Weight of Date | CH65: Total Bins of Date | CL65: Total Weight of Date | CP65: Total Bins of Date

Sheet Parm40#
A1: 008-000006--Parm Blocks 40 lb RW | D1: Ttl. Tts. | E1: =F64+N64+V64+AD64+AL64+AT64+BB64+BJ64+BR64+BZ64+CH64+CP64 -> 0 | F1: Ttl. Wt. | G1: =B64+J64+R64+Z64+AH64+AP64+AX64+BF64+BN64+BV64+CD64+CL64 -> 0 | I1: 008-000006--Parm Blocks 40 lb RW | Q1: 008-000006--Parm Blocks 40 lb RW | Y1: 008-000006--Parm Blocks 40 lb RW | AG1: 008-000006--Parm Blocks 40 lb RW | AO1: 008-000006--Parm Blocks 40 lb RW | AW1: 008-000006--Parm Blocks 40 lb RW | BE1: 008-000006--Parm Blocks 40 lb RW | BM1: 008-000006--Parm Blocks 40 lb RW | BU1: 008-000006--Parm Blocks 40 lb RW | CC1: 008-000006--Parm Blocks 40 lb RW | CK1: 008-000006--Parm Blocks 40 lb RW
B2: Date= | F2: Firmness F=Firm S=Soft | G2: Delvicid Used Y/N | J2: Date= | N2: Firmness F=Firm S=Soft | O2: Delvicid Used Y/N | R2: Date= | V2: Firmness F=Firm S=Soft | W2: Delvicid Used Y/N | Z2: Date= | AD2: Firmness F=Firm S=Soft | AE2: Delvicid Used Y/N | AH2: Date= | AL2: Firmness F=Firm S=Soft | AM2: Delvicid Used Y/N | AP2: Date= | AT2: Firmness F=Firm S=Soft | AU2: Delvicid Used Y/N | AX2: Date= | BB2: Firmness F=Firm S=Soft | BC2: Delvicid Used Y/N | BF2: Date= | BJ2: Firmness F=Firm S=Soft | BK2: Delvicid Used Y/N | BN2: Date= | BR2: Firmness F=Firm S=Soft | BS2: Delvicid Used Y/N | BV2: Date= | BZ2: Firmness F=Firm S=Soft | CA2: Delvicid Used Y/N | CD2: Date= | CH2: Firmness F=Firm S=Soft | CI2: Delvicid Used Y/N | CL2: Date= | CP2: Firmness F=Firm S=Soft | CQ2: Delvicid Used Y/N
